Workbook

Sheet Assumptions
A1: Clinic messaging + AI receptionist - cost model inputs (prices USD, as of 2026-10-29)
A2: Legend: blue = editable input; yellow = key assumption; black = formula. Prices table: col C = Canada patients, col D = US patients. Volume table: col C/D/E = scenario A / B / C (per clinic).
A4: 1. Unit prices
A5: Item | B5: Unit | C5: Canada | D5: US | E5: Source | F5: Verification status
A6: Claude Opus 5.5 input | B6: $/MTok | C6: 4 | D6: 4 | E6: https://platform.claude.com/docs/en/about-claude/pricing | F6: Verified: fetched official page 2026-10-29
A7: Claude Opus 5.5 output | B7: $/MTok | C7: 20 | D7: 20 | E7: https://platform.claude.com/docs/en/about-claude/pricing | F7: Verified: fetched official page 2026-10-29
A8: Claude Opus 5.5 cache read | B8: $/MTok | C8: 0.2 | D8: 0.2 | E8: https://platform.claude.com/docs/en/about-claude/pricing | F8: Verified: fetched official page 2026-10-29
A9: Claude Opus 5.5 cache write 5-min (1.25x) | B9: $/MTok | C9: 5 | D9: 5 | E9: https://platform.claude.com/docs/en/about-claude/pricing | F9: Verified: fetched official page 2026-10-29
A10: Claude Opus 5.5 cache write 1-hour (2x) | B10: $/MTok | C10: 8 | D10: 8 | E10: https://platform.claude.com/docs/en/about-claude/pricing | F10: Verified: fetched official page 2026-10-29
A11: Claude Sonnet 5.5 input | B11: $/MTok | C11: 2 | D11: 2 | E11: https://platform.claude.com/docs/en/about-claude/pricing | F11: Verified: fetched official page 2026-10-29
A12: Claude Sonnet 5.5 output | B12: $/MTok | C12: 10 | D12: 10 | E12: https://platform.claude.com/docs/en/about-claude/pricing | F12: Verified: fetched official page 2026-10-29
A13: Claude Sonnet 5.5 cache read | B13: $/MTok | C13: 0.1 | D13: 0.1 | E13: https://platform.claude.com/docs/en/about-claude/pricing | F13: Verified: fetched official page 2026-10-29
A14: Claude Sonnet 5.5 cache write 5-min (1.25x) | B14: $/MTok | C14: 2.5 | D14: 2.5 | E14: https://platform.claude.com/docs/en/about-claude/pricing | F14: Verified: fetched official page 2026-10-29
A15: Claude Sonnet 5.5 cache write 1-hour (2x) | B15: $/MTok | C15: 4 | D15: 4 | E15: https://platform.claude.com/docs/en/about-claude/pricing | F15: Verified: fetched official page 2026-10-29
A16: Claude Haiku 5.5 (prompts <=100K) input | B16: $/MTok | C16: 0.1 | D16: 0.1 | E16: https://platform.claude.com/docs/en/about-claude/pricing | F16: Verified: fetched official page 2026-10-29
A17: Claude Haiku 5.5 (prompts <=100K) output | B17: $/MTok | C17: 0.5 | D17: 0.5 | E17: https://platform.claude.com/docs/en/about-claude/pricing | F17: Verified: fetched official page 2026-10-29
... A33: Telnyx 10DLC campaign monthly | B33: $/month | C33: 0 | D33: 2 | E33: https://telnyx.com/pricing/messaging | F33: US only. Telnyx says '$2-$30 by use case' - exact low-volume fee NOT VERIFIED
A34: Months to amortise one-time fees | B34: months | C34: 12 | D34: 12 | F34: Assumption (modelling input)
A35: Meta WhatsApp utility template (North America) | B35: $/msg | C35: 0.0034 | D35: 0.0034 | E35: https://developers.facebook.com/documentation/business-messaging/whatsapp/pricing | F35: NOT VERIFIED on official page - third-party/derived; re-verify (Meta page confirms CA+US share 'North America' rates; figure from third-party rate tables)
A36: Meta WhatsApp authentication template | B36: $/msg | C36: 0.0034 | D36: 0.0034 | E36: https://developers.facebook.com/documentation/business-messaging/whatsapp/pricing | F36: NOT VERIFIED on official page - third-party/derived; re-verify
A37: Meta WhatsApp marketing template | B37: $/msg | C37: 0.025 | D37: 0.025 | E37: https://developers.facebook.com/documentation/business-messaging/whatsapp/pricing | F37: NOT VERIFIED on official page - third-party/derived; re-verify
A38: Meta WhatsApp service (free-form) msg beyond free tier | B38: $/msg | C38: 0.0034 | D38: 0.0034 | E38: https://developers.facebook.com/documentation/business-messaging/whatsapp/pricing ; https://help.twilio.com/articles/53100480177819 | F38: Charged from 2026-10-01 at utility rate (third-party). 1,000 free/month/number from Meta page via search. NOT VERIFIED on official page - third-party/derived; re-verify
A39: Free service messages per business number | B39: msgs/month | C39: 1000 | D39: 1000 | E39: https://developers.facebook.com/documentation/business-messaging/whatsapp/pricing ; https://help.twilio.com/articles/53100480177819 | F39: Official page seen via search index only (direct fetch blocked) - re-verify
A40: WhatsApp marketing deliverable to +1 US numbers? (1=yes,0=no) | B40: flag | C40: 1 | D40: 0 | E40: Meta paused US marketing templates since 2025-04-01 | F40: Third-party reports pause still active Jul 2026; NOT VERIFIED for Oct 2026
A41: Twilio WhatsApp fee per message (sent OR received) | B41: $/msg | C41: 0.005 | D41: 0.005 | E41: https://www.twilio.com/en-us/whatsapp/pricing | F41: Official page seen via search index only (direct fetch blocked) - re-verify
A42: Messenger / Instagram DM per message | B42: $/msg | C42: 0 | D42: 0 | E42: https://developers.facebook.com/docs/messenger-platform/ | F42: No per-message fee found; NOT VERIFIED on a pricing page
A43: ElevenLabs Agents per call minute (overage = effective rate on all plans) | B43: $/min | C43: 0.08 | D43: 0.08 | E43: https://elevenlabs.io/pricing/agents | F43: Official page seen via search index only (direct fetch blocked) - re-verify (Creator $22/275 min, Pro $99/1,238, Scale $299/3,738, Business $990/12,375; burst over concurrency = $0.16)
A44: ElevenLabs-hosted LLM pass-through | B44: $/min | C44: 0.01 | D44: 0.01 | E44: https://elevenlabs.io/pricing/agents | F44: ASSUMPTION - LLM billed separately per model; ElevenLabs shows estimate in dashboard. Not verified
A45: Twilio inbound local call (Programmable Voice, native integration) | B45: $/min | C45: 0.0085 | D45: 0.0085 | E45: https://www.twilio.com/en-us/voice/pricing/ca ; https://www.twilio.com/en-us/voice/pricing/us | F45: Official page seen via search index only (direct fetch blocked) - re-verify
A46: Twilio Elastic SIP origination, local | B46: $/min | C46: 0.0034 | D46: 0.0034 | E46: https://www.twilio.com/en-us/sip-trunking/pricing/us | F46: US: Official page seen via search index only (direct fetch blocked) - re-verify. CA: NOT VERIFIED
... A54: Scenario C SendGrid Pro (100K) | B54: $/month | C54: 89.95 | D54: 89.95 | E54: https://www.twilio.com/en-us/products/email-api/pricing | F54: Official page seen via search index only (direct fetch blocked) - re-verify
A56: 2. AI token footprint (per API call)
A57: Item | B57: Unit | C57: Value | E57: Source | F57: Notes
A58: Cacheable prefix: system prompt 1,450 + tools 1,160 + tool-use system prompt 286 | B58: tokens | C58: 2896 | E58: src/ai/prompt.ts, src/ai/tools.ts ; https://platform.claude.com/docs/en/about-claude/pricing | F58: Above the 512-token cache minimum for Opus/Sonnet/Haiku 5.5 (https://platform.claude.com/docs/en/build-with-claude/prompt-caching)
A59: Per-turn context (uncached, after cache breakpoint) | B59: tokens | C59: 80 | E59: From brief / measured in code | F59: turnContext()
A60: Average conversation history per call | B60: tokens | C60: 300 | E60: From brief / measured in code | F60: ~150 tokens/message, avg over 3 messages
A61: Average tool-loop carry (tool_use + tool_result + prior thinking) | B61: tokens | C61: 125 | E61: Assumption | F61: ~250 tokens per extra round, avg 2 calls/message
A62: Output per call incl. tool calls + low-effort adaptive thinking | B62: tokens | C62: 140 | E62: Assumption | F62: reply 120 + tool call 60 + thinking ~50 per call, averaged over 2 calls
A63: Patient messages per text conversation | B63: msgs | C63: 3 | E63: From brief / measured in code
A64: API calls per patient message | B64: calls | C64: 2 | E64: From brief / measured in code | F64: 1-3 (tool loop)
...

Sheet A-Canada
A1: Scenario A - Canada patients - monthly cost (USD)
A2: Scenario (A/B/C) | B2: A
A3: Patient country (CA/US) | B3: CA
A5: Volumes (whole scenario)
A6: Clinics | B6: =IF($B$2="A",Assumptions!$C$81,IF($B$2="B",Assumptions!$D$81,Assumptions!$E$81)) -> 1
A7: Inbound SMS | B7: =IF($B$2="A",Assumptions!$C$82,IF($B$2="B",Assumptions!$D$82,Assumptions!$E$82))*$B$6 -> 300
A8: Outbound SMS | B8: =IF($B$2="A",Assumptions!$C$83,IF($B$2="B",Assumptions!$D$83,Assumptions!$E$83))*$B$6 -> 600
A9: Marketing templates | B9: =IF($B$2="A",Assumptions!$C$86,IF($B$2="B",Assumptions!$D$86,Assumptions!$E$86))*$B$6 -> 80
A10: marketing sent on WhatsApp | B10: =B9*IF($B$3="CA",Assumptions!$C$40,Assumptions!$D$40) -> 80
A11: marketing sent as SMS (US pause) | B11: =B9-B10 -> 0
A12: Outbound SMS segments | B12: =(B8+B11)*Assumptions!$C$68 -> 960
A13: Inbound SMS segments | B13: =B7*Assumptions!$C$69 -> 300
A14: WhatsApp conversations | B14: =IF($B$2="A",Assumptions!$C$84,IF($B$2="B",Assumptions!$D$84,Assumptions!$E$84))*$B$6 -> 200
A15: service conversations | B15: =B14*IF($B$2="A",Assumptions!$C$85,IF($B$2="B",Assumptions!$D$85,Assumptions!$E$85)) -> 120
A16: utility templates | B16: =B14-B15 -> 80
A17: WhatsApp service replies (outbound free-form) | B17: =B15*Assumptions!$C$67+B16*Assumptions!$C$66 -> 400
A18: WhatsApp inbound messages | B18: =B15*Assumptions!$C$63+B16*Assumptions!$C$66 -> 400
A19: WhatsApp service msgs billable (after free tier) | B19: =MAX(0,B17-IF($B$3="CA",Assumptions!$C$39,Assumptions!$D$39)*B6) -> 0
A20: Messenger/IG threads | B20: =IF($B$2="A",Assumptions!$C$87,IF($B$2="B",Assumptions!$D$87,Assumptions!$E$87))*$B$6 -> 100
A21: Emails | B21: =IF($B$2="A",Assumptions!$C$89,IF($B$2="B",Assumptions!$D$89,Assumptions!$E$89))*$B$6 -> 300
A22: Calls | B22: =IF($B$2="A",Assumptions!$C$88,IF($B$2="B",Assumptions!$D$88,Assumptions!$E$88))*$B$6 -> 150
A23: ElevenLabs minutes | B23: =B22*Assumptions!$C$70 -> 450
A24: Carrier-billed minutes | B24: =B22*Assumptions!$C$71 -> 525
A25: AI text conversations | B25: =B7/Assumptions!$C$63+B15+B20+B21*Assumptions!$C$65 -> 350
A26: AI API calls (text receptionist) | B26: =B25*Assumptions!$C$63*Assumptions!$C$64+B16*Assumptions!$C$66*Assumptions!$C$64 -> 2180
A27: Booked appointments (1 in 3 of AI text convs + calls) | B27: =(B25+B22)*Assumptions!$C$72 -> 166.66667
A29: Configuration | C29: (i) All-Twilio + ElevenLabs + Opus 5.5 | D29: (ii) Optimised + Opus 5.5 | E29: (iii-a) Optimised + Sonnet 5.5 | F29: (iii-b) Optimised + Haiku 5.5 | G29: (ref) All-Twilio + Opus, NO caching
A30: SMS vendor (Twilio/Telnyx) | C30: Twilio | D30: Telnyx | E30: Telnyx | F30: Telnyx | G30: Twilio
A31: WhatsApp route (Twilio/Meta) | C31: Twilio | D31: Meta | E31: Meta | F31: Meta | G31: Twilio
A32: Voice path (TwilioNative/TwilioSIP/TelnyxSIP) | C32: TwilioNative | D32: TelnyxSIP | E32: TelnyxSIP | F32: TelnyxSIP | G32: TwilioNative
A33: Email (SendGrid/Postmark/Paubox/Best) | C33: SendGrid | D33: Best | E33: Best | F33: Best | G33: SendGrid
A34: Text model (opus/sonnet/haiku) | C34: opus | D34: opus | E34: sonnet | F34: haiku | G34: opus
A35: Prompt cache TTL (5m/1h/none) | C35: 5m | D35: 1h | E35: 1h | F35: 1h | G35: none
A37: AI cost per API call
A38: Input price $/MTok | C38: =IF(C34="opus",Assumptions!$C$6,IF(C34="sonnet",Assumptions!$C$11,Assumptions!$C$16))*Assumptions!$C$21 -> 4 | D38: =IF(D34="opus",Assumptions!$C$6,IF(D34="sonnet",Assumptions!$C$11,Assumptions!$C$16))*Assumptions!$C$21 -> 4 | E38: =IF(E34="opus",Assumptions!$C$6,IF(E34="sonnet",Assumptions!$C$11,Assumptions!$C$16))*Assumptions!$C$21 -> 2 | F38: =IF(F34="opus",Assumptions!$C$6,IF(F34="sonnet",Assumptions!$C$11,Assumptions!$C$16))*Assumptions!$C$21 -> 0.1 | G38: =IF(G34="opus",Assumptions!$C$6,IF(G34="sonnet",Assumptions!$C$11,Assumptions!$C$16))*Assumptions!$C$21 -> 4
A39: Output price $/MTok | C39: =IF(C34="opus",Assumptions!$C$7,IF(C34="sonnet",Assumptions!$C$12,Assumptions!$C$17))*Assumptions!$C$21 -> 20 | D39: =IF(D34="opus",Assumptions!$C$7,IF(D34="sonnet",Assumptions!$C$12,Assumptions!$C$17))*Assumptions!$C$21 -> 20 | E39: =IF(E34="opus",Assumptions!$C$7,IF(E34="sonnet",Assumptions!$C$12,Assumptions!$C$17))*Assumptions!$C$21 -> 10 | F39: =IF(F34="opus",Assumptions!$C$7,IF(F34="sonnet",Assumptions!$C$12,Assumptions!$C$17))*Assumptions!$C$21 -> 0.5 | G39: =IF(G34="opus",Assumptions!$C$7,IF(G34="sonnet",Assumptions!$C$12,Assumptions!$C$17))*Assumptions!$C$21 -> 20
A40: Cache read $/MTok | C40: =IF(C34="opus",Assumptions!$C$8,IF(C34="sonnet",Assumptions!$C$13,Assumptions!$C$18))*Assumptions!$C$21 -> 0.2 | D40: =IF(D34="opus",Assumptions!$C$8,IF(D34="sonnet",Assumptions!$C$13,Assumptions!$C$18))*Assumptions!$C$21 -> 0.2 | E40: =IF(E34="opus",Assumptions!$C$8,IF(E34="sonnet",Assumptions!$C$13,Assumptions!$C$18))*Assumptions!$C$21 -> 0.1 | F40: =IF(F34="opus",Assumptions!$C$8,IF(F34="sonnet",Assumptions!$C$13,Assumptions!$C$18))*Assumptions!$C$21 -> 0.01 | G40: =IF(G34="opus",Assumptions!$C$8,IF(G34="sonnet",Assumptions!$C$13,Assumptions!$C$18))*Assumptions!$C$21 -> 0.2
A41: Cache write $/MTok (per TTL) | C41: =IF(C35="5m",IF(C34="opus",Assumptions!$C$9,IF(C34="sonnet",Assumptions!$C$14,Assumptions!$C$19)),IF(C35="1h",IF(C34="opus",Assumptions!$C$10,IF(C34="sonnet",Assumptions!$C$15,Assumptions!$C$20)),0))*Assumptions!$C$21 -> 5 | D41: =IF(D35="5m",IF(D34="opus",Assumptions!$C$9,IF(D34="sonnet",Assumptions!$C$14,Assumptions!$C$19)),IF(D35="1h",IF(D34="opus",Assumptions!$C$10,IF(D34="sonnet",Assumptions!$C$15,Assumptions!$C$20)),0))*Assumptions!$C$21 -> 8 | E41: =IF(E35="5m",IF(E34="opus",Assumptions!$C$9,IF(E34="sonnet",Assumptions!$C$14,Assumptions!$C$19)),IF(E35="1h",IF(E34="opus",Assumptions!$C$10,IF(E34="sonnet",Assumptions!$C$15,Assumptions!$C$20)),0))*Assumptions!$C$21 -> 4 | F41: =IF(F35="5m",IF(F34="opus",Assumptions!$C$9,IF(F34="sonnet",Assumptions!$C$14,Assumptions!$C$19)),IF(F35="1h",IF(F34="opus",Assumptions!$C$10,IF(F34="sonnet",Assumptions!$C$15,Assumptions!$C$20)),0))*Assumptions!$C$21 -> 0.2 | G41: =IF(G35="5m",IF(G34="opus",Assumptions!$C$9,IF(G34="sonnet",Assumptions!$C$14,Assumptions!$C$19)),IF(G35="1h",IF(G34="opus",Assumptions!$C$10,IF(G34="sonnet",Assumptions!$C$15,Assumptions!$C$20)),0))*Assumptions!$C$21 -> 0
A42: Cache write fraction | C42: =IF(C35="5m",IF($B$2="A",Assumptions!$C$76,IF($B$2="B",Assumptions!$D$76,Assumptions!$E$76)),IF(C35="1h",IF($B$2="A",Assumptions!$C$77,IF($B$2="B",Assumptions!$D$77,Assumptions!$E$77)),1)) -> 0.375 | D42: =IF(D35="5m",IF($B$2="A",Assumptions!$C$76,IF($B$2="B",Assumptions!$D$76,Assumptions!$E$76)),IF(D35="1h",IF($B$2="A",Assumptions!$C$77,IF($B$2="B",Assumptions!$D$77,Assumptions!$E$77)),1)) -> 0.05 | E42: =IF(E35="5m",IF($B$2="A",Assumptions!$C$76,IF($B$2="B",Assumptions!$D$76,Assumptions!$E$76)),IF(E35="1h",IF($B$2="A",Assumptions!$C$77,IF($B$2="B",Assumptions!$D$77,Assumptions!$E$77)),1)) -> 0.05 | F42: =IF(F35="5m",IF($B$2="A",Assumptions!$C$76,IF($B$2="B",Assumptions!$D$76,Assumptions!$E$76)),IF(F35="1h",IF($B$2="A",Assumptions!$C$77,IF($B$2="B",Assumptions!$D$77,Assumptions!$E$77)),1)) -> 0.05 | G42: =IF(G35="5m",IF($B$2="A",Assumptions!$C$76,IF($B$2="B",Assumptions!$D$76,Assumptions!$E$76)),IF(G35="1h",IF($B$2="A",Assumptions!$C$77,IF($B$2="B",Assumptions!$D$77,Assumptions!$E$77)),1)) -> 1
A43: Prefix cost/call $ | C43: =IF(C35="none",Assumptions!$C$58*C38,Assumptions!$C$58*(C42*C41+(1-C42)*C40))/1000000 -> 0.005792 | D43: =IF(D35="none",Assumptions!$C$58*D38,Assumptions!$C$58*(D42*D41+(1-D42)*D40))/1000000 -> 0.00170864 | E43: =IF(E35="none",Assumptions!$C$58*E38,Assumptions!$C$58*(E42*E41+(1-E42)*E40))/1000000 -> 0.00085432 | F43: =IF(F35="none",Assumptions!$C$58*F38,Assumptions!$C$58*(F42*F41+(1-F42)*F40))/1000000 -> 5.6472e-05 | G43: =IF(G35="none",Assumptions!$C$58*G38,Assumptions!$C$58*(G42*G41+(1-G42)*G40))/1000000 -> 0.011584
...

Sheet A-US
A1: Scenario A - US patients - monthly cost (USD)
A2: Scenario (A/B/C) | B2: A
A3: Patient country (CA/US) | B3: US
A5: Volumes (whole scenario)
A6: Clinics | B6: =IF($B$2="A",Assumptions!$C$81,IF($B$2="B",Assumptions!$D$81,Assumptions!$E$81)) -> 1
A7: Inbound SMS | B7: =IF($B$2="A",Assumptions!$C$82,IF($B$2="B",Assumptions!$D$82,Assumptions!$E$82))*$B$6 -> 300
A8: Outbound SMS | B8: =IF($B$2="A",Assumptions!$C$83,IF($B$2="B",Assumptions!$D$83,Assumptions!$E$83))*$B$6 -> 600
A9: Marketing templates | B9: =IF($B$2="A",Assumptions!$C$86,IF($B$2="B",Assumptions!$D$86,Assumptions!$E$86))*$B$6 -> 80
A10: marketing sent on WhatsApp | B10: =B9*IF($B$3="CA",Assumptions!$C$40,Assumptions!$D$40) -> 0
A11: marketing sent as SMS (US pause) | B11: =B9-B10 -> 80
A12: Outbound SMS segments | B12: =(B8+B11)*Assumptions!$C$68 -> 1088
A13: Inbound SMS segments | B13: =B7*Assumptions!$C$69 -> 300
A14: WhatsApp conversations | B14: =IF($B$2="A",Assumptions!$C$84,IF($B$2="B",Assumptions!$D$84,Assumptions!$E$84))*$B$6 -> 200
A15: service conversations | B15: =B14*IF($B$2="A",Assumptions!$C$85,IF($B$2="B",Assumptions!$D$85,Assumptions!$E$85)) -> 120
A16: utility templates | B16: =B14-B15 -> 80
A17: WhatsApp service replies (outbound free-form) | B17: =B15*Assumptions!$C$67+B16*Assumptions!$C$66 -> 400
A18: WhatsApp inbound messages | B18: =B15*Assumptions!$C$63+B16*Assumptions!$C$66 -> 400
A19: WhatsApp service msgs billable (after free tier) | B19: =MAX(0,B17-IF($B$3="CA",Assumptions!$C$39,Assumptions!$D$39)*B6) -> 0
A20: Messenger/IG threads | B20: =IF($B$2="A",Assumptions!$C$87,IF($B$2="B",Assumptions!$D$87,Assumptions!$E$87))*$B$6 -> 100
A21: Emails | B21: =IF($B$2="A",Assumptions!$C$89,IF($B$2="B",Assumptions!$D$89,Assumptions!$E$89))*$B$6 -> 300
A22: Calls | B22: =IF($B$2="A",Assumptions!$C$88,IF($B$2="B",Assumptions!$D$88,Assumptions!$E$88))*$B$6 -> 150
A23: ElevenLabs minutes | B23: =B22*Assumptions!$C$70 -> 450
A24: Carrier-billed minutes | B24: =B22*Assumptions!$C$71 -> 525
A25: AI text conversations | B25: =B7/Assumptions!$C$63+B15+B20+B21*Assumptions!$C$65 -> 350
A26: AI API calls (text receptionist) | B26: =B25*Assumptions!$C$63*Assumptions!$C$64+B16*Assumptions!$C$66*Assumptions!$C$64 -> 2180
A27: Booked appointments (1 in 3 of AI text convs + calls) | B27: =(B25+B22)*Assumptions!$C$72 -> 166.66667
A29: Configuration | C29: (i) All-Twilio + ElevenLabs + Opus 5.5 | D29: (ii) Optimised + Opus 5.5 | E29: (iii-a) Optimised + Sonnet 5.5 | F29: (iii-b) Optimised + Haiku 5.5 | G29: (ref) All-Twilio + Opus, NO caching
A30: SMS vendor (Twilio/Telnyx) | C30: Twilio | D30: Telnyx | E30: Telnyx | F30: Telnyx | G30: Twilio
A31: WhatsApp route (Twilio/Meta) | C31: Twilio | D31: Meta | E31: Meta | F31: Meta | G31: Twilio
A32: Voice path (TwilioNative/TwilioSIP/TelnyxSIP) | C32: TwilioNative | D32: TelnyxSIP | E32: TelnyxSIP | F32: TelnyxSIP | G32: TwilioNative
A33: Email (SendGrid/Postmark/Paubox/Best) | C33: SendGrid | D33: Best | E33: Best | F33: Best | G33: SendGrid
A34: Text model (opus/sonnet/haiku) | C34: opus | D34: opus | E34: sonnet | F34: haiku | G34: opus
A35: Prompt cache TTL (5m/1h/none) | C35: 5m | D35: 1h | E35: 1h | F35: 1h | G35: none
A37: AI cost per API call
A38: Input price $/MTok | C38: =IF(C34="opus",Assumptions!$C$6,IF(C34="sonnet",Assumptions!$C$11,Assumptions!$C$16))*Assumptions!$C$21 -> 4 | D38: =IF(D34="opus",Assumptions!$C$6,IF(D34="sonnet",Assumptions!$C$11,Assumptions!$C$16))*Assumptions!$C$21 -> 4 | E38: =IF(E34="opus",Assumptions!$C$6,IF(E34="sonnet",Assumptions!$C$11,Assumptions!$C$16))*Assumptions!$C$21 -> 2 | F38: =IF(F34="opus",Assumptions!$C$6,IF(F34="sonnet",Assumptions!$C$11,Assumptions!$C$16))*Assumptions!$C$21 -> 0.1 | G38: =IF(G34="opus",Assumptions!$C$6,IF(G34="sonnet",Assumptions!$C$11,Assumptions!$C$16))*Assumptions!$C$21 -> 4
A39: Output price $/MTok | C39: =IF(C34="opus",Assumptions!$C$7,IF(C34="sonnet",Assumptions!$C$12,Assumptions!$C$17))*Assumptions!$C$21 -> 20 | D39: =IF(D34="opus",Assumptions!$C$7,IF(D34="sonnet",Assumptions!$C$12,Assumptions!$C$17))*Assumptions!$C$21 -> 20 | E39: =IF(E34="opus",Assumptions!$C$7,IF(E34="sonnet",Assumptions!$C$12,Assumptions!$C$17))*Assumptions!$C$21 -> 10 | F39: =IF(F34="opus",Assumptions!$C$7,IF(F34="sonnet",Assumptions!$C$12,Assumptions!$C$17))*Assumptions!$C$21 -> 0.5 | G39: =IF(G34="opus",Assumptions!$C$7,IF(G34="sonnet",Assumptions!$C$12,Assumptions!$C$17))*Assumptions!$C$21 -> 20
A40: Cache read $/MTok | C40: =IF(C34="opus",Assumptions!$C$8,IF(C34="sonnet",Assumptions!$C$13,Assumptions!$C$18))*Assumptions!$C$21 -> 0.2 | D40: =IF(D34="opus",Assumptions!$C$8,IF(D34="sonnet",Assumptions!$C$13,Assumptions!$C$18))*Assumptions!$C$21 -> 0.2 | E40: =IF(E34="opus",Assumptions!$C$8,IF(E34="sonnet",Assumptions!$C$13,Assumptions!$C$18))*Assumptions!$C$21 -> 0.1 | F40: =IF(F34="opus",Assumptions!$C$8,IF(F34="sonnet",Assumptions!$C$13,Assumptions!$C$18))*Assumptions!$C$21 -> 0.01 | G40: =IF(G34="opus",Assumptions!$C$8,IF(G34="sonnet",Assumptions!$C$13,Assumptions!$C$18))*Assumptions!$C$21 -> 0.2
A41: Cache write $/MTok (per TTL) | C41: =IF(C35="5m",IF(C34="opus",Assumptions!$C$9,IF(C34="sonnet",Assumptions!$C$14,Assumptions!$C$19)),IF(C35="1h",IF(C34="opus",Assumptions!$C$10,IF(C34="sonnet",Assumptions!$C$15,Assumptions!$C$20)),0))*Assumptions!$C$21 -> 5 | D41: =IF(D35="5m",IF(D34="opus",Assumptions!$C$9,IF(D34="sonnet",Assumptions!$C$14,Assumptions!$C$19)),IF(D35="1h",IF(D34="opus",Assumptions!$C$10,IF(D34="sonnet",Assumptions!$C$15,Assumptions!$C$20)),0))*Assumptions!$C$21 -> 8 | E41: =IF(E35="5m",IF(E34="opus",Assumptions!$C$9,IF(E34="sonnet",Assumptions!$C$14,Assumptions!$C$19)),IF(E35="1h",IF(E34="opus",Assumptions!$C$10,IF(E34="sonnet",Assumptions!$C$15,Assumptions!$C$20)),0))*Assumptions!$C$21 -> 4 | F41: =IF(F35="5m",IF(F34="opus",Assumptions!$C$9,IF(F34="sonnet",Assumptions!$C$14,Assumptions!$C$19)),IF(F35="1h",IF(F34="opus",Assumptions!$C$10,IF(F34="sonnet",Assumptions!$C$15,Assumptions!$C$20)),0))*Assumptions!$C$21 -> 0.2 | G41: =IF(G35="5m",IF(G34="opus",Assumptions!$C$9,IF(G34="sonnet",Assumptions!$C$14,Assumptions!$C$19)),IF(G35="1h",IF(G34="opus",Assumptions!$C$10,IF(G34="sonnet",Assumptions!$C$15,Assumptions!$C$20)),0))*Assumptions!$C$21 -> 0
A42: Cache write fraction | C42: =IF(C35="5m",IF($B$2="A",Assumptions!$C$76,IF($B$2="B",Assumptions!$D$76,Assumptions!$E$76)),IF(C35="1h",IF($B$2="A",Assumptions!$C$77,IF($B$2="B",Assumptions!$D$77,Assumptions!$E$77)),1)) -> 0.375 | D42: =IF(D35="5m",IF($B$2="A",Assumptions!$C$76,IF($B$2="B",Assumptions!$D$76,Assumptions!$E$76)),IF(D35="1h",IF($B$2="A",Assumptions!$C$77,IF($B$2="B",Assumptions!$D$77,Assumptions!$E$77)),1)) -> 0.05 | E42: =IF(E35="5m",IF($B$2="A",Assumptions!$C$76,IF($B$2="B",Assumptions!$D$76,Assumptions!$E$76)),IF(E35="1h",IF($B$2="A",Assumptions!$C$77,IF($B$2="B",Assumptions!$D$77,Assumptions!$E$77)),1)) -> 0.05 | F42: =IF(F35="5m",IF($B$2="A",Assumptions!$C$76,IF($B$2="B",Assumptions!$D$76,Assumptions!$E$76)),IF(F35="1h",IF($B$2="A",Assumptions!$C$77,IF($B$2="B",Assumptions!$D$77,Assumptions!$E$77)),1)) -> 0.05 | G42: =IF(G35="5m",IF($B$2="A",Assumptions!$C$76,IF($B$2="B",Assumptions!$D$76,Assumptions!$E$76)),IF(G35="1h",IF($B$2="A",Assumptions!$C$77,IF($B$2="B",Assumptions!$D$77,Assumptions!$E$77)),1)) -> 1
A43: Prefix cost/call $ | C43: =IF(C35="none",Assumptions!$C$58*C38,Assumptions!$C$58*(C42*C41+(1-C42)*C40))/1000000 -> 0.005792 | D43: =IF(D35="none",Assumptions!$C$58*D38,Assumptions!$C$58*(D42*D41+(1-D42)*D40))/1000000 -> 0.00170864 | E43: =IF(E35="none",Assumptions!$C$58*E38,Assumptions!$C$58*(E42*E41+(1-E42)*E40))/1000000 -> 0.00085432 | F43: =IF(F35="none",Assumptions!$C$58*F38,Assumptions!$C$58*(F42*F41+(1-F42)*F40))/1000000 -> 5.6472e-05 | G43: =IF(G35="none",Assumptions!$C$58*G38,Assumptions!$C$58*(G42*G41+(1-G42)*G40))/1000000 -> 0.011584
...

Sheet B-Canada
A1: Scenario B - Canada patients - monthly cost (USD)
A2: Scenario (A/B/C) | B2: B
A3: Patient country (CA/US) | B3: CA
A5: Volumes (whole scenario)
A6: Clinics | B6: =IF($B$2="A",Assumptions!$C$81,IF($B$2="B",Assumptions!$D$81,Assumptions!$E$81)) -> 1
A7: Inbound SMS | B7: =IF($B$2="A",Assumptions!$C$82,IF($B$2="B",Assumptions!$D$82,Assumptions!$E$82))*$B$6 -> 1500
A8: Outbound SMS | B8: =IF($B$2="A",Assumptions!$C$83,IF($B$2="B",Assumptions!$D$83,Assumptions!$E$83))*$B$6 -> 3000
A9: Marketing templates | B9: =IF($B$2="A",Assumptions!$C$86,IF($B$2="B",Assumptions!$D$86,Assumptions!$E$86))*$B$6 -> 400
A10: marketing sent on WhatsApp | B10: =B9*IF($B$3="CA",Assumptions!$C$40,Assumptions!$D$40) -> 400
A11: marketing sent as SMS (US pause) | B11: =B9-B10 -> 0
A12: Outbound SMS segments | B12: =(B8+B11)*Assumptions!$C$68 -> 4800
A13: Inbound SMS segments | B13: =B7*Assumptions!$C$69 -> 1500
A14: WhatsApp conversations | B14: =IF($B$2="A",Assumptions!$C$84,IF($B$2="B",Assumptions!$D$84,Assumptions!$E$84))*$B$6 -> 800
A15: service conversations | B15: =B14*IF($B$2="A",Assumptions!$C$85,IF($B$2="B",Assumptions!$D$85,Assumptions!$E$85)) -> 480
A16: utility templates | B16: =B14-B15 -> 320
A17: WhatsApp service replies (outbound free-form) | B17: =B15*Assumptions!$C$67+B16*Assumptions!$C$66 -> 1600
A18: WhatsApp inbound messages | B18: =B15*Assumptions!$C$63+B16*Assumptions!$C$66 -> 1600
A19: WhatsApp service msgs billable (after free tier) | B19: =MAX(0,B17-IF($B$3="CA",Assumptions!$C$39,Assumptions!$D$39)*B6) -> 600
A20: Messenger/IG threads | B20: =IF($B$2="A",Assumptions!$C$87,IF($B$2="B",Assumptions!$D$87,Assumptions!$E$87))*$B$6 -> 300
A21: Emails | B21: =IF($B$2="A",Assumptions!$C$89,IF($B$2="B",Assumptions!$D$89,Assumptions!$E$89))*$B$6 -> 1500
A22: Calls | B22: =IF($B$2="A",Assumptions!$C$88,IF($B$2="B",Assumptions!$D$88,Assumptions!$E$88))*$B$6 -> 600
A23: ElevenLabs minutes | B23: =B22*Assumptions!$C$70 -> 1800
A24: Carrier-billed minutes | B24: =B22*Assumptions!$C$71 -> 2100
A25: AI text conversations | B25: =B7/Assumptions!$C$63+B15+B20+B21*Assumptions!$C$65 -> 1430
A26: AI API calls (text receptionist) | B26: =B25*Assumptions!$C$63*Assumptions!$C$64+B16*Assumptions!$C$66*Assumptions!$C$64 -> 8900
A27: Booked appointments (1 in 3 of AI text convs + calls) | B27: =(B25+B22)*Assumptions!$C$72 -> 676.66667
A29: Configuration | C29: (i) All-Twilio + ElevenLabs + Opus 5.5 | D29: (ii) Optimised + Opus 5.5 | E29: (iii-a) Optimised + Sonnet 5.5 | F29: (iii-b) Optimised + Haiku 5.5 | G29: (ref) All-Twilio + Opus, NO caching
A30: SMS vendor (Twilio/Telnyx) | C30: Twilio | D30: Telnyx | E30: Telnyx | F30: Telnyx | G30: Twilio
A31: WhatsApp route (Twilio/Meta) | C31: Twilio | D31: Meta | E31: Meta | F31: Meta | G31: Twilio
A32: Voice path (TwilioNative/TwilioSIP/TelnyxSIP) | C32: TwilioNative | D32: TelnyxSIP | E32: TelnyxSIP | F32: TelnyxSIP | G32: TwilioNative
A33: Email (SendGrid/Postmark/Paubox/Best) | C33: SendGrid | D33: Best | E33: Best | F33: Best | G33: SendGrid
A34: Text model (opus/sonnet/haiku) | C34: opus | D34: opus | E34: sonnet | F34: haiku | G34: opus
A35: Prompt cache TTL (5m/1h/none) | C35: 5m | D35: 1h | E35: 1h | F35: 1h | G35: none
A37: AI cost per API call
A38: Input price $/MTok | C38: =IF(C34="opus",Assumptions!$C$6,IF(C34="sonnet",Assumptions!$C$11,Assumptions!$C$16))*Assumptions!$C$21 -> 4 | D38: =IF(D34="opus",Assumptions!$C$6,IF(D34="sonnet",Assumptions!$C$11,Assumptions!$C$16))*Assumptions!$C$21 -> 4 | E38: =IF(E34="opus",Assumptions!$C$6,IF(E34="sonnet",Assumptions!$C$11,Assumptions!$C$16))*Assumptions!$C$21 -> 2 | F38: =IF(F34="opus",Assumptions!$C$6,IF(F34="sonnet",Assumptions!$C$11,Assumptions!$C$16))*Assumptions!$C$21 -> 0.1 | G38: =IF(G34="opus",Assumptions!$C$6,IF(G34="sonnet",Assumptions!$C$11,Assumptions!$C$16))*Assumptions!$C$21 -> 4
A39: Output price $/MTok | C39: =IF(C34="opus",Assumptions!$C$7,IF(C34="sonnet",Assumptions!$C$12,Assumptions!$C$17))*Assumptions!$C$21 -> 20 | D39: =IF(D34="opus",Assumptions!$C$7,IF(D34="sonnet",Assumptions!$C$12,Assumptions!$C$17))*Assumptions!$C$21 -> 20 | E39: =IF(E34="opus",Assumptions!$C$7,IF(E34="sonnet",Assumptions!$C$12,Assumptions!$C$17))*Assumptions!$C$21 -> 10 | F39: =IF(F34="opus",Assumptions!$C$7,IF(F34="sonnet",Assumptions!$C$12,Assumptions!$C$17))*Assumptions!$C$21 -> 0.5 | G39: =IF(G34="opus",Assumptions!$C$7,IF(G34="sonnet",Assumptions!$C$12,Assumptions!$C$17))*Assumptions!$C$21 -> 20
A40: Cache read $/MTok | C40: =IF(C34="opus",Assumptions!$C$8,IF(C34="sonnet",Assumptions!$C$13,Assumptions!$C$18))*Assumptions!$C$21 -> 0.2 | D40: =IF(D34="opus",Assumptions!$C$8,IF(D34="sonnet",Assumptions!$C$13,Assumptions!$C$18))*Assumptions!$C$21 -> 0.2 | E40: =IF(E34="opus",Assumptions!$C$8,IF(E34="sonnet",Assumptions!$C$13,Assumptions!$C$18))*Assumptions!$C$21 -> 0.1 | F40: =IF(F34="opus",Assumptions!$C$8,IF(F34="sonnet",Assumptions!$C$13,Assumptions!$C$18))*Assumptions!$C$21 -> 0.01 | G40: =IF(G34="opus",Assumptions!$C$8,IF(G34="sonnet",Assumptions!$C$13,Assumptions!$C$18))*Assumptions!$C$21 -> 0.2
A41: Cache write $/MTok (per TTL) | C41: =IF(C35="5m",IF(C34="opus",Assumptions!$C$9,IF(C34="sonnet",Assumptions!$C$14,Assumptions!$C$19)),IF(C35="1h",IF(C34="opus",Assumptions!$C$10,IF(C34="sonnet",Assumptions!$C$15,Assumptions!$C$20)),0))*Assumptions!$C$21 -> 5 | D41: =IF(D35="5m",IF(D34="opus",Assumptions!$C$9,IF(D34="sonnet",Assumptions!$C$14,Assumptions!$C$19)),IF(D35="1h",IF(D34="opus",Assumptions!$C$10,IF(D34="sonnet",Assumptions!$C$15,Assumptions!$C$20)),0))*Assumptions!$C$21 -> 8 | E41: =IF(E35="5m",IF(E34="opus",Assumptions!$C$9,IF(E34="sonnet",Assumptions!$C$14,Assumptions!$C$19)),IF(E35="1h",IF(E34="opus",Assumptions!$C$10,IF(E34="sonnet",Assumptions!$C$15,Assumptions!$C$20)),0))*Assumptions!$C$21 -> 4 | F41: =IF(F35="5m",IF(F34="opus",Assumptions!$C$9,IF(F34="sonnet",Assumptions!$C$14,Assumptions!$C$19)),IF(F35="1h",IF(F34="opus",Assumptions!$C$10,IF(F34="sonnet",Assumptions!$C$15,Assumptions!$C$20)),0))*Assumptions!$C$21 -> 0.2 | G41: =IF(G35="5m",IF(G34="opus",Assumptions!$C$9,IF(G34="sonnet",Assumptions!$C$14,Assumptions!$C$19)),IF(G35="1h",IF(G34="opus",Assumptions!$C$10,IF(G34="sonnet",Assumptions!$C$15,Assumptions!$C$20)),0))*Assumptions!$C$21 -> 0
A42: Cache write fraction | C42: =IF(C35="5m",IF($B$2="A",Assumptions!$C$76,IF($B$2="B",Assumptions!$D$76,Assumptions!$E$76)),IF(C35="1h",IF($B$2="A",Assumptions!$C$77,IF($B$2="B",Assumptions!$D$77,Assumptions!$E$77)),1)) -> 0.15 | D42: =IF(D35="5m",IF($B$2="A",Assumptions!$C$76,IF($B$2="B",Assumptions!$D$76,Assumptions!$E$76)),IF(D35="1h",IF($B$2="A",Assumptions!$C$77,IF($B$2="B",Assumptions!$D$77,Assumptions!$E$77)),1)) -> 0.03 | E42: =IF(E35="5m",IF($B$2="A",Assumptions!$C$76,IF($B$2="B",Assumptions!$D$76,Assumptions!$E$76)),IF(E35="1h",IF($B$2="A",Assumptions!$C$77,IF($B$2="B",Assumptions!$D$77,Assumptions!$E$77)),1)) -> 0.03 | F42: =IF(F35="5m",IF($B$2="A",Assumptions!$C$76,IF($B$2="B",Assumptions!$D$76,Assumptions!$E$76)),IF(F35="1h",IF($B$2="A",Assumptions!$C$77,IF($B$2="B",Assumptions!$D$77,Assumptions!$E$77)),1)) -> 0.03 | G42: =IF(G35="5m",IF($B$2="A",Assumptions!$C$76,IF($B$2="B",Assumptions!$D$76,Assumptions!$E$76)),IF(G35="1h",IF($B$2="A",Assumptions!$C$77,IF($B$2="B",Assumptions!$D$77,Assumptions!$E$77)),1)) -> 1
A43: Prefix cost/call $ | C43: =IF(C35="none",Assumptions!$C$58*C38,Assumptions!$C$58*(C42*C41+(1-C42)*C40))/1000000 -> 0.00266432 | D43: =IF(D35="none",Assumptions!$C$58*D38,Assumptions!$C$58*(D42*D41+(1-D42)*D40))/1000000 -> 0.001256864 | E43: =IF(E35="none",Assumptions!$C$58*E38,Assumptions!$C$58*(E42*E41+(1-E42)*E40))/1000000 -> 0.000628432 | F43: =IF(F35="none",Assumptions!$C$58*F38,Assumptions!$C$58*(F42*F41+(1-F42)*F40))/1000000 -> 4.54672e-05 | G43: =IF(G35="none",Assumptions!$C$58*G38,Assumptions!$C$58*(G42*G41+(1-G42)*G40))/1000000 -> 0.011584
...

Sheet B-US
A1: Scenario B - US patients - monthly cost (USD)
A2: Scenario (A/B/C) | B2: B
A3: Patient country (CA/US) | B3: US
A5: Volumes (whole scenario)
A6: Clinics | B6: =IF($B$2="A",Assumptions!$C$81,IF($B$2="B",Assumptions!$D$81,Assumptions!$E$81)) -> 1
A7: Inbound SMS | B7: =IF($B$2="A",Assumptions!$C$82,IF($B$2="B",Assumptions!$D$82,Assumptions!$E$82))*$B$6 -> 1500
A8: Outbound SMS | B8: =IF($B$2="A",Assumptions!$C$83,IF($B$2="B",Assumptions!$D$83,Assumptions!$E$83))*$B$6 -> 3000
A9: Marketing templates | B9: =IF($B$2="A",Assumptions!$C$86,IF($B$2="B",Assumptions!$D$86,Assumptions!$E$86))*$B$6 -> 400
A10: marketing sent on WhatsApp | B10: =B9*IF($B$3="CA",Assumptions!$C$40,Assumptions!$D$40) -> 0
A11: marketing sent as SMS (US pause) | B11: =B9-B10 -> 400
A12: Outbound SMS segments | B12: =(B8+B11)*Assumptions!$C$68 -> 5440
A13: Inbound SMS segments | B13: =B7*Assumptions!$C$69 -> 1500
A14: WhatsApp conversations | B14: =IF($B$2="A",Assumptions!$C$84,IF($B$2="B",Assumptions!$D$84,Assumptions!$E$84))*$B$6 -> 800
A15: service conversations | B15: =B14*IF($B$2="A",Assumptions!$C$85,IF($B$2="B",Assumptions!$D$85,Assumptions!$E$85)) -> 480
A16: utility templates | B16: =B14-B15 -> 320
A17: WhatsApp service replies (outbound free-form) | B17: =B15*Assumptions!$C$67+B16*Assumptions!$C$66 -> 1600
A18: WhatsApp inbound messages | B18: =B15*Assumptions!$C$63+B16*Assumptions!$C$66 -> 1600
A19: WhatsApp service msgs billable (after free tier) | B19: =MAX(0,B17-IF($B$3="CA",Assumptions!$C$39,Assumptions!$D$39)*B6) -> 600
A20: Messenger/IG threads | B20: =IF($B$2="A",Assumptions!$C$87,IF($B$2="B",Assumptions!$D$87,Assumptions!$E$87))*$B$6 -> 300
A21: Emails | B21: =IF($B$2="A",Assumptions!$C$89,IF($B$2="B",Assumptions!$D$89,Assumptions!$E$89))*$B$6 -> 1500
A22: Calls | B22: =IF($B$2="A",Assumptions!$C$88,IF($B$2="B",Assumptions!$D$88,Assumptions!$E$88))*$B$6 -> 600
A23: ElevenLabs minutes | B23: =B22*Assumptions!$C$70 -> 1800
A24: Carrier-billed minutes | B24: =B22*Assumptions!$C$71 -> 2100
A25: AI text conversations | B25: =B7/Assumptions!$C$63+B15+B20+B21*Assumptions!$C$65 -> 1430
A26: AI API calls (text receptionist) | B26: =B25*Assumptions!$C$63*Assumptions!$C$64+B16*Assumptions!$C$66*Assumptions!$C$64 -> 8900
A27: Booked appointments (1 in 3 of AI text convs + calls) | B27: =(B25+B22)*Assumptions!$C$72 -> 676.66667
A29: Configuration | C29: (i) All-Twilio + ElevenLabs + Opus 5.5 | D29: (ii) Optimised + Opus 5.5 | E29: (iii-a) Optimised + Sonnet 5.5 | F29: (iii-b) Optimised + Haiku 5.5 | G29: (ref) All-Twilio + Opus, NO caching
A30: SMS vendor (Twilio/Telnyx) | C30: Twilio | D30: Telnyx | E30: Telnyx | F30: Telnyx | G30: Twilio
A31: WhatsApp route (Twilio/Meta) | C31: Twilio | D31: Meta | E31: Meta | F31: Meta | G31: Twilio
A32: Voice path (TwilioNative/TwilioSIP/TelnyxSIP) | C32: TwilioNative | D32: TelnyxSIP | E32: TelnyxSIP | F32: TelnyxSIP | G32: TwilioNative
A33: Email (SendGrid/Postmark/Paubox/Best) | C33: SendGrid | D33: Best | E33: Best | F33: Best | G33: SendGrid
A34: Text model (opus/sonnet/haiku) | C34: opus | D34: opus | E34: sonnet | F34: haiku | G34: opus
A35: Prompt cache TTL (5m/1h/none) | C35: 5m | D35: 1h | E35: 1h | F35: 1h | G35: none
A37: AI cost per API call
A38: Input price $/MTok | C38: =IF(C34="opus",Assumptions!$C$6,IF(C34="sonnet",Assumptions!$C$11,Assumptions!$C$16))*Assumptions!$C$21 -> 4 | D38: =IF(D34="opus",Assumptions!$C$6,IF(D34="sonnet",Assumptions!$C$11,Assumptions!$C$16))*Assumptions!$C$21 -> 4 | E38: =IF(E34="opus",Assumptions!$C$6,IF(E34="sonnet",Assumptions!$C$11,Assumptions!$C$16))*Assumptions!$C$21 -> 2 | F38: =IF(F34="opus",Assumptions!$C$6,IF(F34="sonnet",Assumptions!$C$11,Assumptions!$C$16))*Assumptions!$C$21 -> 0.1 | G38: =IF(G34="opus",Assumptions!$C$6,IF(G34="sonnet",Assumptions!$C$11,Assumptions!$C$16))*Assumptions!$C$21 -> 4
A39: Output price $/MTok | C39: =IF(C34="opus",Assumptions!$C$7,IF(C34="sonnet",Assumptions!$C$12,Assumptions!$C$17))*Assumptions!$C$21 -> 20 | D39: =IF(D34="opus",Assumptions!$C$7,IF(D34="sonnet",Assumptions!$C$12,Assumptions!$C$17))*Assumptions!$C$21 -> 20 | E39: =IF(E34="opus",Assumptions!$C$7,IF(E34="sonnet",Assumptions!$C$12,Assumptions!$C$17))*Assumptions!$C$21 -> 10 | F39: =IF(F34="opus",Assumptions!$C$7,IF(F34="sonnet",Assumptions!$C$12,Assumptions!$C$17))*Assumptions!$C$21 -> 0.5 | G39: =IF(G34="opus",Assumptions!$C$7,IF(G34="sonnet",Assumptions!$C$12,Assumptions!$C$17))*Assumptions!$C$21 -> 20
A40: Cache read $/MTok | C40: =IF(C34="opus",Assumptions!$C$8,IF(C34="sonnet",Assumptions!$C$13,Assumptions!$C$18))*Assumptions!$C$21 -> 0.2 | D40: =IF(D34="opus",Assumptions!$C$8,IF(D34="sonnet",Assumptions!$C$13,Assumptions!$C$18))*Assumptions!$C$21 -> 0.2 | E40: =IF(E34="opus",Assumptions!$C$8,IF(E34="sonnet",Assumptions!$C$13,Assumptions!$C$18))*Assumptions!$C$21 -> 0.1 | F40: =IF(F34="opus",Assumptions!$C$8,IF(F34="sonnet",Assumptions!$C$13,Assumptions!$C$18))*Assumptions!$C$21 -> 0.01 | G40: =IF(G34="opus",Assumptions!$C$8,IF(G34="sonnet",Assumptions!$C$13,Assumptions!$C$18))*Assumptions!$C$21 -> 0.2
A41: Cache write $/MTok (per TTL) | C41: =IF(C35="5m",IF(C34="opus",Assumptions!$C$9,IF(C34="sonnet",Assumptions!$C$14,Assumptions!$C$19)),IF(C35="1h",IF(C34="opus",Assumptions!$C$10,IF(C34="sonnet",Assumptions!$C$15,Assumptions!$C$20)),0))*Assumptions!$C$21 -> 5 | D41: =IF(D35="5m",IF(D34="opus",Assumptions!$C$9,IF(D34="sonnet",Assumptions!$C$14,Assumptions!$C$19)),IF(D35="1h",IF(D34="opus",Assumptions!$C$10,IF(D34="sonnet",Assumptions!$C$15,Assumptions!$C$20)),0))*Assumptions!$C$21 -> 8 | E41: =IF(E35="5m",IF(E34="opus",Assumptions!$C$9,IF(E34="sonnet",Assumptions!$C$14,Assumptions!$C$19)),IF(E35="1h",IF(E34="opus",Assumptions!$C$10,IF(E34="sonnet",Assumptions!$C$15,Assumptions!$C$20)),0))*Assumptions!$C$21 -> 4 | F41: =IF(F35="5m",IF(F34="opus",Assumptions!$C$9,IF(F34="sonnet",Assumptions!$C$14,Assumptions!$C$19)),IF(F35="1h",IF(F34="opus",Assumptions!$C$10,IF(F34="sonnet",Assumptions!$C$15,Assumptions!$C$20)),0))*Assumptions!$C$21 -> 0.2 | G41: =IF(G35="5m",IF(G34="opus",Assumptions!$C$9,IF(G34="sonnet",Assumptions!$C$14,Assumptions!$C$19)),IF(G35="1h",IF(G34="opus",Assumptions!$C$10,IF(G34="sonnet",Assumptions!$C$15,Assumptions!$C$20)),0))*Assumptions!$C$21 -> 0
A42: Cache write fraction | C42: =IF(C35="5m",IF($B$2="A",Assumptions!$C$76,IF($B$2="B",Assumptions!$D$76,Assumptions!$E$76)),IF(C35="1h",IF($B$2="A",Assumptions!$C$77,IF($B$2="B",Assumptions!$D$77,Assumptions!$E$77)),1)) -> 0.15 | D42: =IF(D35="5m",IF($B$2="A",Assumptions!$C$76,IF($B$2="B",Assumptions!$D$76,Assumptions!$E$76)),IF(D35="1h",IF($B$2="A",Assumptions!$C$77,IF($B$2="B",Assumptions!$D$77,Assumptions!$E$77)),1)) -> 0.03 | E42: =IF(E35="5m",IF($B$2="A",Assumptions!$C$76,IF($B$2="B",Assumptions!$D$76,Assumptions!$E$76)),IF(E35="1h",IF($B$2="A",Assumptions!$C$77,IF($B$2="B",Assumptions!$D$77,Assumptions!$E$77)),1)) -> 0.03 | F42: =IF(F35="5m",IF($B$2="A",Assumptions!$C$76,IF($B$2="B",Assumptions!$D$76,Assumptions!$E$76)),IF(F35="1h",IF($B$2="A",Assumptions!$C$77,IF($B$2="B",Assumptions!$D$77,Assumptions!$E$77)),1)) -> 0.03 | G42: =IF(G35="5m",IF($B$2="A",Assumptions!$C$76,IF($B$2="B",Assumptions!$D$76,Assumptions!$E$76)),IF(G35="1h",IF($B$2="A",Assumptions!$C$77,IF($B$2="B",Assumptions!$D$77,Assumptions!$E$77)),1)) -> 1
A43: Prefix cost/call $ | C43: =IF(C35="none",Assumptions!$C$58*C38,Assumptions!$C$58*(C42*C41+(1-C42)*C40))/1000000 -> 0.00266432 | D43: =IF(D35="none",Assumptions!$C$58*D38,Assumptions!$C$58*(D42*D41+(1-D42)*D40))/1000000 -> 0.001256864 | E43: =IF(E35="none",Assumptions!$C$58*E38,Assumptions!$C$58*(E42*E41+(1-E42)*E40))/1000000 -> 0.000628432 | F43: =IF(F35="none",Assumptions!$C$58*F38,Assumptions!$C$58*(F42*F41+(1-F42)*F40))/1000000 -> 4.54672e-05 | G43: =IF(G35="none",Assumptions!$C$58*G38,Assumptions!$C$58*(G42*G41+(1-G42)*G40))/1000000 -> 0.011584
...

Sheet C-Canada
A1: Scenario C - Canada patients - monthly cost (USD)
A2: Scenario (A/B/C) | B2: C
A3: Patient country (CA/US) | B3: CA
A5: Volumes (whole scenario)
A6: Clinics | B6: =IF($B$2="A",Assumptions!$C$81,IF($B$2="B",Assumptions!$D$81,Assumptions!$E$81)) -> 50
A7: Inbound SMS | B7: =IF($B$2="A",Assumptions!$C$82,IF($B$2="B",Assumptions!$D$82,Assumptions!$E$82))*$B$6 -> 75000
A8: Outbound SMS | B8: =IF($B$2="A",Assumptions!$C$83,IF($B$2="B",Assumptions!$D$83,Assumptions!$E$83))*$B$6 -> 150000
A9: Marketing templates | B9: =IF($B$2="A",Assumptions!$C$86,IF($B$2="B",Assumptions!$D$86,Assumptions!$E$86))*$B$6 -> 20000
A10: marketing sent on WhatsApp | B10: =B9*IF($B$3="CA",Assumptions!$C$40,Assumptions!$D$40) -> 20000
A11: marketing sent as SMS (US pause) | B11: =B9-B10 -> 0
A12: Outbound SMS segments | B12: =(B8+B11)*Assumptions!$C$68 -> 240000
A13: Inbound SMS segments | B13: =B7*Assumptions!$C$69 -> 75000
A14: WhatsApp conversations | B14: =IF($B$2="A",Assumptions!$C$84,IF($B$2="B",Assumptions!$D$84,Assumptions!$E$84))*$B$6 -> 40000
A15: service conversations | B15: =B14*IF($B$2="A",Assumptions!$C$85,IF($B$2="B",Assumptions!$D$85,Assumptions!$E$85)) -> 24000
A16: utility templates | B16: =B14-B15 -> 16000
A17: WhatsApp service replies (outbound free-form) | B17: =B15*Assumptions!$C$67+B16*Assumptions!$C$66 -> 80000
A18: WhatsApp inbound messages | B18: =B15*Assumptions!$C$63+B16*Assumptions!$C$66 -> 80000
A19: WhatsApp service msgs billable (after free tier) | B19: =MAX(0,B17-IF($B$3="CA",Assumptions!$C$39,Assumptions!$D$39)*B6) -> 30000
A20: Messenger/IG threads | B20: =IF($B$2="A",Assumptions!$C$87,IF($B$2="B",Assumptions!$D$87,Assumptions!$E$87))*$B$6 -> 15000
A21: Emails | B21: =IF($B$2="A",Assumptions!$C$89,IF($B$2="B",Assumptions!$D$89,Assumptions!$E$89))*$B$6 -> 75000
A22: Calls | B22: =IF($B$2="A",Assumptions!$C$88,IF($B$2="B",Assumptions!$D$88,Assumptions!$E$88))*$B$6 -> 30000
A23: ElevenLabs minutes | B23: =B22*Assumptions!$C$70 -> 90000
A24: Carrier-billed minutes | B24: =B22*Assumptions!$C$71 -> 105000
A25: AI text conversations | B25: =B7/Assumptions!$C$63+B15+B20+B21*Assumptions!$C$65 -> 71500
A26: AI API calls (text receptionist) | B26: =B25*Assumptions!$C$63*Assumptions!$C$64+B16*Assumptions!$C$66*Assumptions!$C$64 -> 445000
A27: Booked appointments (1 in 3 of AI text convs + calls) | B27: =(B25+B22)*Assumptions!$C$72 -> 33833.333
A29: Configuration | C29: (i) All-Twilio + ElevenLabs + Opus 5.5 | D29: (ii) Optimised + Opus 5.5 | E29: (iii-a) Optimised + Sonnet 5.5 | F29: (iii-b) Optimised + Haiku 5.5 | G29: (ref) All-Twilio + Opus, NO caching
A30: SMS vendor (Twilio/Telnyx) | C30: Twilio | D30: Telnyx | E30: Telnyx | F30: Telnyx | G30: Twilio
A31: WhatsApp route (Twilio/Meta) | C31: Twilio | D31: Meta | E31: Meta | F31: Meta | G31: Twilio
A32: Voice path (TwilioNative/TwilioSIP/TelnyxSIP) | C32: TwilioNative | D32: TelnyxSIP | E32: TelnyxSIP | F32: TelnyxSIP | G32: TwilioNative
A33: Email (SendGrid/Postmark/Paubox/Best) | C33: SendGrid | D33: Best | E33: Best | F33: Best | G33: SendGrid
A34: Text model (opus/sonnet/haiku) | C34: opus | D34: opus | E34: sonnet | F34: haiku | G34: opus
A35: Prompt cache TTL (5m/1h/none) | C35: 5m | D35: 1h | E35: 1h | F35: 1h | G35: none
A37: AI cost per API call
A38: Input price $/MTok | C38: =IF(C34="opus",Assumptions!$C$6,IF(C34="sonnet",Assumptions!$C$11,Assumptions!$C$16))*Assumptions!$C$21 -> 4 | D38: =IF(D34="opus",Assumptions!$C$6,IF(D34="sonnet",Assumptions!$C$11,Assumptions!$C$16))*Assumptions!$C$21 -> 4 | E38: =IF(E34="opus",Assumptions!$C$6,IF(E34="sonnet",Assumptions!$C$11,Assumptions!$C$16))*Assumptions!$C$21 -> 2 | F38: =IF(F34="opus",Assumptions!$C$6,IF(F34="sonnet",Assumptions!$C$11,Assumptions!$C$16))*Assumptions!$C$21 -> 0.1 | G38: =IF(G34="opus",Assumptions!$C$6,IF(G34="sonnet",Assumptions!$C$11,Assumptions!$C$16))*Assumptions!$C$21 -> 4
A39: Output price $/MTok | C39: =IF(C34="opus",Assumptions!$C$7,IF(C34="sonnet",Assumptions!$C$12,Assumptions!$C$17))*Assumptions!$C$21 -> 20 | D39: =IF(D34="opus",Assumptions!$C$7,IF(D34="sonnet",Assumptions!$C$12,Assumptions!$C$17))*Assumptions!$C$21 -> 20 | E39: =IF(E34="opus",Assumptions!$C$7,IF(E34="sonnet",Assumptions!$C$12,Assumptions!$C$17))*Assumptions!$C$21 -> 10 | F39: =IF(F34="opus",Assumptions!$C$7,IF(F34="sonnet",Assumptions!$C$12,Assumptions!$C$17))*Assumptions!$C$21 -> 0.5 | G39: =IF(G34="opus",Assumptions!$C$7,IF(G34="sonnet",Assumptions!$C$12,Assumptions!$C$17))*Assumptions!$C$21 -> 20
A40: Cache read $/MTok | C40: =IF(C34="opus",Assumptions!$C$8,IF(C34="sonnet",Assumptions!$C$13,Assumptions!$C$18))*Assumptions!$C$21 -> 0.2 | D40: =IF(D34="opus",Assumptions!$C$8,IF(D34="sonnet",Assumptions!$C$13,Assumptions!$C$18))*Assumptions!$C$21 -> 0.2 | E40: =IF(E34="opus",Assumptions!$C$8,IF(E34="sonnet",Assumptions!$C$13,Assumptions!$C$18))*Assumptions!$C$21 -> 0.1 | F40: =IF(F34="opus",Assumptions!$C$8,IF(F34="sonnet",Assumptions!$C$13,Assumptions!$C$18))*Assumptions!$C$21 -> 0.01 | G40: =IF(G34="opus",Assumptions!$C$8,IF(G34="sonnet",Assumptions!$C$13,Assumptions!$C$18))*Assumptions!$C$21 -> 0.2
A41: Cache write $/MTok (per TTL) | C41: =IF(C35="5m",IF(C34="opus",Assumptions!$C$9,IF(C34="sonnet",Assumptions!$C$14,Assumptions!$C$19)),IF(C35="1h",IF(C34="opus",Assumptions!$C$10,IF(C34="sonnet",Assumptions!$C$15,Assumptions!$C$20)),0))*Assumptions!$C$21 -> 5 | D41: =IF(D35="5m",IF(D34="opus",Assumptions!$C$9,IF(D34="sonnet",Assumptions!$C$14,Assumptions!$C$19)),IF(D35="1h",IF(D34="opus",Assumptions!$C$10,IF(D34="sonnet",Assumptions!$C$15,Assumptions!$C$20)),0))*Assumptions!$C$21 -> 8 | E41: =IF(E35="5m",IF(E34="opus",Assumptions!$C$9,IF(E34="sonnet",Assumptions!$C$14,Assumptions!$C$19)),IF(E35="1h",IF(E34="opus",Assumptions!$C$10,IF(E34="sonnet",Assumptions!$C$15,Assumptions!$C$20)),0))*Assumptions!$C$21 -> 4 | F41: =IF(F35="5m",IF(F34="opus",Assumptions!$C$9,IF(F34="sonnet",Assumptions!$C$14,Assumptions!$C$19)),IF(F35="1h",IF(F34="opus",Assumptions!$C$10,IF(F34="sonnet",Assumptions!$C$15,Assumptions!$C$20)),0))*Assumptions!$C$21 -> 0.2 | G41: =IF(G35="5m",IF(G34="opus",Assumptions!$C$9,IF(G34="sonnet",Assumptions!$C$14,Assumptions!$C$19)),IF(G35="1h",IF(G34="opus",Assumptions!$C$10,IF(G34="sonnet",Assumptions!$C$15,Assumptions!$C$20)),0))*Assumptions!$C$21 -> 0
A42: Cache write fraction | C42: =IF(C35="5m",IF($B$2="A",Assumptions!$C$76,IF($B$2="B",Assumptions!$D$76,Assumptions!$E$76)),IF(C35="1h",IF($B$2="A",Assumptions!$C$77,IF($B$2="B",Assumptions!$D$77,Assumptions!$E$77)),1)) -> 0.15 | D42: =IF(D35="5m",IF($B$2="A",Assumptions!$C$76,IF($B$2="B",Assumptions!$D$76,Assumptions!$E$76)),IF(D35="1h",IF($B$2="A",Assumptions!$C$77,IF($B$2="B",Assumptions!$D$77,Assumptions!$E$77)),1)) -> 0.03 | E42: =IF(E35="5m",IF($B$2="A",Assumptions!$C$76,IF($B$2="B",Assumptions!$D$76,Assumptions!$E$76)),IF(E35="1h",IF($B$2="A",Assumptions!$C$77,IF($B$2="B",Assumptions!$D$77,Assumptions!$E$77)),1)) -> 0.03 | F42: =IF(F35="5m",IF($B$2="A",Assumptions!$C$76,IF($B$2="B",Assumptions!$D$76,Assumptions!$E$76)),IF(F35="1h",IF($B$2="A",Assumptions!$C$77,IF($B$2="B",Assumptions!$D$77,Assumptions!$E$77)),1)) -> 0.03 | G42: =IF(G35="5m",IF($B$2="A",Assumptions!$C$76,IF($B$2="B",Assumptions!$D$76,Assumptions!$E$76)),IF(G35="1h",IF($B$2="A",Assumptions!$C$77,IF($B$2="B",Assumptions!$D$77,Assumptions!$E$77)),1)) -> 1
A43: Prefix cost/call $ | C43: =IF(C35="none",Assumptions!$C$58*C38,Assumptions!$C$58*(C42*C41+(1-C42)*C40))/1000000 -> 0.00266432 | D43: =IF(D35="none",Assumptions!$C$58*D38,Assumptions!$C$58*(D42*D41+(1-D42)*D40))/1000000 -> 0.001256864 | E43: =IF(E35="none",Assumptions!$C$58*E38,Assumptions!$C$58*(E42*E41+(1-E42)*E40))/1000000 -> 0.000628432 | F43: =IF(F35="none",Assumptions!$C$58*F38,Assumptions!$C$58*(F42*F41+(1-F42)*F40))/1000000 -> 4.54672e-05 | G43: =IF(G35="none",Assumptions!$C$58*G38,Assumptions!$C$58*(G42*G41+(1-G42)*G40))/1000000 -> 0.011584
...

Sheet C-US
A1: Scenario C - US patients - monthly cost (USD)
A2: Scenario (A/B/C) | B2: C
A3: Patient country (CA/US) | B3: US
A5: Volumes (whole scenario)
A6: Clinics | B6: =IF($B$2="A",Assumptions!$C$81,IF($B$2="B",Assumptions!$D$81,Assumptions!$E$81)) -> 50
A7: Inbound SMS | B7: =IF($B$2="A",Assumptions!$C$82,IF($B$2="B",Assumptions!$D$82,Assumptions!$E$82))*$B$6 -> 75000
A8: Outbound SMS | B8: =IF($B$2="A",Assumptions!$C$83,IF($B$2="B",Assumptions!$D$83,Assumptions!$E$83))*$B$6 -> 150000
A9: Marketing templates | B9: =IF($B$2="A",Assumptions!$C$86,IF($B$2="B",Assumptions!$D$86,Assumptions!$E$86))*$B$6 -> 20000
A10: marketing sent on WhatsApp | B10: =B9*IF($B$3="CA",Assumptions!$C$40,Assumptions!$D$40) -> 0
A11: marketing sent as SMS (US pause) | B11: =B9-B10 -> 20000
A12: Outbound SMS segments | B12: =(B8+B11)*Assumptions!$C$68 -> 272000
A13: Inbound SMS segments | B13: =B7*Assumptions!$C$69 -> 75000
A14: WhatsApp conversations | B14: =IF($B$2="A",Assumptions!$C$84,IF($B$2="B",Assumptions!$D$84,Assumptions!$E$84))*$B$6 -> 40000
A15: service conversations | B15: =B14*IF($B$2="A",Assumptions!$C$85,IF($B$2="B",Assumptions!$D$85,Assumptions!$E$85)) -> 24000
A16: utility templates | B16: =B14-B15 -> 16000
A17: WhatsApp service replies (outbound free-form) | B17: =B15*Assumptions!$C$67+B16*Assumptions!$C$66 -> 80000
A18: WhatsApp inbound messages | B18: =B15*Assumptions!$C$63+B16*Assumptions!$C$66 -> 80000
A19: WhatsApp service msgs billable (after free tier) | B19: =MAX(0,B17-IF($B$3="CA",Assumptions!$C$39,Assumptions!$D$39)*B6) -> 30000
A20: Messenger/IG threads | B20: =IF($B$2="A",Assumptions!$C$87,IF($B$2="B",Assumptions!$D$87,Assumptions!$E$87))*$B$6 -> 15000
A21: Emails | B21: =IF($B$2="A",Assumptions!$C$89,IF($B$2="B",Assumptions!$D$89,Assumptions!$E$89))*$B$6 -> 75000
A22: Calls | B22: =IF($B$2="A",Assumptions!$C$88,IF($B$2="B",Assumptions!$D$88,Assumptions!$E$88))*$B$6 -> 30000
A23: ElevenLabs minutes | B23: =B22*Assumptions!$C$70 -> 90000
A24: Carrier-billed minutes | B24: =B22*Assumptions!$C$71 -> 105000
A25: AI text conversations | B25: =B7/Assumptions!$C$63+B15+B20+B21*Assumptions!$C$65 -> 71500
A26: AI API calls (text receptionist) | B26: =B25*Assumptions!$C$63*Assumptions!$C$64+B16*Assumptions!$C$66*Assumptions!$C$64 -> 445000
A27: Booked appointments (1 in 3 of AI text convs + calls) | B27: =(B25+B22)*Assumptions!$C$72 -> 33833.333
A29: Configuration | C29: (i) All-Twilio + ElevenLabs + Opus 5.5 | D29: (ii) Optimised + Opus 5.5 | E29: (iii-a) Optimised + Sonnet 5.5 | F29: (iii-b) Optimised + Haiku 5.5 | G29: (ref) All-Twilio + Opus, NO caching
A30: SMS vendor (Twilio/Telnyx) | C30: Twilio | D30: Telnyx | E30: Telnyx | F30: Telnyx | G30: Twilio
A31: WhatsApp route (Twilio/Meta) | C31: Twilio | D31: Meta | E31: Meta | F31: Meta | G31: Twilio
A32: Voice path (TwilioNative/TwilioSIP/TelnyxSIP) | C32: TwilioNative | D32: TelnyxSIP | E32: TelnyxSIP | F32: TelnyxSIP | G32: TwilioNative
A33: Email (SendGrid/Postmark/Paubox/Best) | C33: SendGrid | D33: Best | E33: Best | F33: Best | G33: SendGrid
A34: Text model (opus/sonnet/haiku) | C34: opus | D34: opus | E34: sonnet | F34: haiku | G34: opus
A35: Prompt cache TTL (5m/1h/none) | C35: 5m | D35: 1h | E35: 1h | F35: 1h | G35: none
A37: AI cost per API call
A38: Input price $/MTok | C38: =IF(C34="opus",Assumptions!$C$6,IF(C34="sonnet",Assumptions!$C$11,Assumptions!$C$16))*Assumptions!$C$21 -> 4 | D38: =IF(D34="opus",Assumptions!$C$6,IF(D34="sonnet",Assumptions!$C$11,Assumptions!$C$16))*Assumptions!$C$21 -> 4 | E38: =IF(E34="opus",Assumptions!$C$6,IF(E34="sonnet",Assumptions!$C$11,Assumptions!$C$16))*Assumptions!$C$21 -> 2 | F38: =IF(F34="opus",Assumptions!$C$6,IF(F34="sonnet",Assumptions!$C$11,Assumptions!$C$16))*Assumptions!$C$21 -> 0.1 | G38: =IF(G34="opus",Assumptions!$C$6,IF(G34="sonnet",Assumptions!$C$11,Assumptions!$C$16))*Assumptions!$C$21 -> 4
A39: Output price $/MTok | C39: =IF(C34="opus",Assumptions!$C$7,IF(C34="sonnet",Assumptions!$C$12,Assumptions!$C$17))*Assumptions!$C$21 -> 20 | D39: =IF(D34="opus",Assumptions!$C$7,IF(D34="sonnet",Assumptions!$C$12,Assumptions!$C$17))*Assumptions!$C$21 -> 20 | E39: =IF(E34="opus",Assumptions!$C$7,IF(E34="sonnet",Assumptions!$C$12,Assumptions!$C$17))*Assumptions!$C$21 -> 10 | F39: =IF(F34="opus",Assumptions!$C$7,IF(F34="sonnet",Assumptions!$C$12,Assumptions!$C$17))*Assumptions!$C$21 -> 0.5 | G39: =IF(G34="opus",Assumptions!$C$7,IF(G34="sonnet",Assumptions!$C$12,Assumptions!$C$17))*Assumptions!$C$21 -> 20
A40: Cache read $/MTok | C40: =IF(C34="opus",Assumptions!$C$8,IF(C34="sonnet",Assumptions!$C$13,Assumptions!$C$18))*Assumptions!$C$21 -> 0.2 | D40: =IF(D34="opus",Assumptions!$C$8,IF(D34="sonnet",Assumptions!$C$13,Assumptions!$C$18))*Assumptions!$C$21 -> 0.2 | E40: =IF(E34="opus",Assumptions!$C$8,IF(E34="sonnet",Assumptions!$C$13,Assumptions!$C$18))*Assumptions!$C$21 -> 0.1 | F40: =IF(F34="opus",Assumptions!$C$8,IF(F34="sonnet",Assumptions!$C$13,Assumptions!$C$18))*Assumptions!$C$21 -> 0.01 | G40: =IF(G34="opus",Assumptions!$C$8,IF(G34="sonnet",Assumptions!$C$13,Assumptions!$C$18))*Assumptions!$C$21 -> 0.2
A41: Cache write $/MTok (per TTL) | C41: =IF(C35="5m",IF(C34="opus",Assumptions!$C$9,IF(C34="sonnet",Assumptions!$C$14,Assumptions!$C$19)),IF(C35="1h",IF(C34="opus",Assumptions!$C$10,IF(C34="sonnet",Assumptions!$C$15,Assumptions!$C$20)),0))*Assumptions!$C$21 -> 5 | D41: =IF(D35="5m",IF(D34="opus",Assumptions!$C$9,IF(D34="sonnet",Assumptions!$C$14,Assumptions!$C$19)),IF(D35="1h",IF(D34="opus",Assumptions!$C$10,IF(D34="sonnet",Assumptions!$C$15,Assumptions!$C$20)),0))*Assumptions!$C$21 -> 8 | E41: =IF(E35="5m",IF(E34="opus",Assumptions!$C$9,IF(E34="sonnet",Assumptions!$C$14,Assumptions!$C$19)),IF(E35="1h",IF(E34="opus",Assumptions!$C$10,IF(E34="sonnet",Assumptions!$C$15,Assumptions!$C$20)),0))*Assumptions!$C$21 -> 4 | F41: =IF(F35="5m",IF(F34="opus",Assumptions!$C$9,IF(F34="sonnet",Assumptions!$C$14,Assumptions!$C$19)),IF(F35="1h",IF(F34="opus",Assumptions!$C$10,IF(F34="sonnet",Assumptions!$C$15,Assumptions!$C$20)),0))*Assumptions!$C$21 -> 0.2 | G41: =IF(G35="5m",IF(G34="opus",Assumptions!$C$9,IF(G34="sonnet",Assumptions!$C$14,Assumptions!$C$19)),IF(G35="1h",IF(G34="opus",Assumptions!$C$10,IF(G34="sonnet",Assumptions!$C$15,Assumptions!$C$20)),0))*Assumptions!$C$21 -> 0
A42: Cache write fraction | C42: =IF(C35="5m",IF($B$2="A",Assumptions!$C$76,IF($B$2="B",Assumptions!$D$76,Assumptions!$E$76)),IF(C35="1h",IF($B$2="A",Assumptions!$C$77,IF($B$2="B",Assumptions!$D$77,Assumptions!$E$77)),1)) -> 0.15 | D42: =IF(D35="5m",IF($B$2="A",Assumptions!$C$76,IF($B$2="B",Assumptions!$D$76,Assumptions!$E$76)),IF(D35="1h",IF($B$2="A",Assumptions!$C$77,IF($B$2="B",Assumptions!$D$77,Assumptions!$E$77)),1)) -> 0.03 | E42: =IF(E35="5m",IF($B$2="A",Assumptions!$C$76,IF($B$2="B",Assumptions!$D$76,Assumptions!$E$76)),IF(E35="1h",IF($B$2="A",Assumptions!$C$77,IF($B$2="B",Assumptions!$D$77,Assumptions!$E$77)),1)) -> 0.03 | F42: =IF(F35="5m",IF($B$2="A",Assumptions!$C$76,IF($B$2="B",Assumptions!$D$76,Assumptions!$E$76)),IF(F35="1h",IF($B$2="A",Assumptions!$C$77,IF($B$2="B",Assumptions!$D$77,Assumptions!$E$77)),1)) -> 0.03 | G42: =IF(G35="5m",IF($B$2="A",Assumptions!$C$76,IF($B$2="B",Assumptions!$D$76,Assumptions!$E$76)),IF(G35="1h",IF($B$2="A",Assumptions!$C$77,IF($B$2="B",Assumptions!$D$77,Assumptions!$E$77)),1)) -> 1
A43: Prefix cost/call $ | C43: =IF(C35="none",Assumptions!$C$58*C38,Assumptions!$C$58*(C42*C41+(1-C42)*C40))/1000000 -> 0.00266432 | D43: =IF(D35="none",Assumptions!$C$58*D38,Assumptions!$C$58*(D42*D41+(1-D42)*D40))/1000000 -> 0.001256864 | E43: =IF(E35="none",Assumptions!$C$58*E38,Assumptions!$C$58*(E42*E41+(1-E42)*E40))/1000000 -> 0.000628432 | F43: =IF(F35="none",Assumptions!$C$58*F38,Assumptions!$C$58*(F42*F41+(1-F42)*F40))/1000000 -> 4.54672e-05 | G43: =IF(G35="none",Assumptions!$C$58*G38,Assumptions!$C$58*(G42*G41+(1-G42)*G40))/1000000 -> 0.011584
...

Sheet Comparison
A1: Monthly totals by scenario and configuration (USD)
A3: Scenario | B3: (i) All-Twilio + ElevenLabs + Opus 5.5 | C3: (ii) Optimised + Opus 5.5 | D3: (iii-a) Optimised + Sonnet 5.5 | E3: (iii-b) Optimised + Haiku 5.5 | F3: (ref) All-Twilio + Opus, NO caching
A4: TOTAL per month
A5: A-Canada | B5: ='A-Canada'!C61 -> 114.40666 | C5: ='A-Canada'!D61 -> 87.504435 | D5: ='A-Canada'!E61 -> 80.388218 | E5: ='A-Canada'!F61 -> 73.657799 | F5: ='A-Canada'!G61 -> 127.03322
A6: A-US | B6: ='A-US'!C61 -> 113.84126 | C6: ='A-US'!D61 -> 72.288635 | D6: ='A-US'!E61 -> 65.172418 | E6: ='A-US'!F61 -> 58.441999 | F6: ='A-US'!G61 -> 126.46782
A7: B-Canada | B7: ='B-Canada'!C61 -> 390.97845 | C7: ='B-Canada'!D61 -> 315.63209 | D7: ='B-Canada'!E61 -> 288.59004 | E7: ='B-Canada'!F61 -> 263.02511 | F7: ='B-Canada'!G61 -> 470.3636
A8: B-US | B8: ='B-US'!C61 -> 375.65145 | C8: ='B-US'!D61 -> 384.05309 | D8: ='B-US'!E61 -> 357.01104 | E8: ='B-US'!F61 -> 331.44611 | F8: ='B-US'!G61 -> 455.0366
A9: C-Canada | B9: ='C-Canada'!C61 -> 18641.372 | C9: ='C-Canada'!D61 -> 15124.604 | D9: ='C-Canada'!E61 -> 13772.502 | E9: ='C-Canada'!F61 -> 12494.255 | F9: ='C-Canada'!G61 -> 22610.63
A10: C-US | B10: ='C-US'!C61 -> 17875.022 | C10: ='C-US'!D61 -> 14752.654 | D10: ='C-US'!E61 -> 13400.552 | E10: ='C-US'!F61 -> 12122.305 | F10: ='C-US'!G61 -> 21844.28
A12: Per clinic per month
A13: A-Canada | B13: ='A-Canada'!C62 -> 114.40666 | C13: ='A-Canada'!D62 -> 87.504435 | D13: ='A-Canada'!E62 -> 80.388218 | E13: ='A-Canada'!F62 -> 73.657799 | F13: ='A-Canada'!G62 -> 127.03322
A14: A-US | B14: ='A-US'!C62 -> 113.84126 | C14: ='A-US'!D62 -> 72.288635 | D14: ='A-US'!E62 -> 65.172418 | E14: ='A-US'!F62 -> 58.441999 | F14: ='A-US'!G62 -> 126.46782
A15: B-Canada | B15: ='B-Canada'!C62 -> 390.97845 | C15: ='B-Canada'!D62 -> 315.63209 | D15: ='B-Canada'!E62 -> 288.59004 | E15: ='B-Canada'!F62 -> 263.02511 | F15: ='B-Canada'!G62 -> 470.3636
A16: B-US | B16: ='B-US'!C62 -> 375.65145 | C16: ='B-US'!D62 -> 384.05309 | D16: ='B-US'!E62 -> 357.01104 | E16: ='B-US'!F62 -> 331.44611 | F16: ='B-US'!G62 -> 455.0366
A17: C-Canada | B17: ='C-Canada'!C62 -> 372.82745 | C17: ='C-Canada'!D62 -> 302.49209 | D17: ='C-Canada'!E62 -> 275.45004 | E17: ='C-Canada'!F62 -> 249.88511 | F17: ='C-Canada'!G62 -> 452.2126
A18: C-US | B18: ='C-US'!C62 -> 357.50045 | C18: ='C-US'!D62 -> 295.05309 | D18: ='C-US'!E62 -> 268.01104 | E18: ='C-US'!F62 -> 242.44611 | F18: ='C-US'!G62 -> 436.8856
A20: Cost per booked appointment
A21: A-Canada | B21: ='A-Canada'!C63 -> 0.68643996 | C21: ='A-Canada'!D63 -> 0.52502661 | D21: ='A-Canada'!E63 -> 0.48232931 | E21: ='A-Canada'!F63 -> 0.44194679 | F21: ='A-Canada'!G63 -> 0.76219932
A22: A-US | B22: ='A-US'!C63 -> 0.68304756 | C22: ='A-US'!D63 -> 0.43373181 | D22: ='A-US'!E63 -> 0.39103451 | E22: ='A-US'!F63 -> 0.35065199 | F22: ='A-US'!G63 -> 0.75880692
A23: B-Canada | B23: ='B-Canada'!C63 -> 0.57780066 | C23: ='B-Canada'!D63 -> 0.46645136 | D23: ='B-Canada'!E63 -> 0.42648775 | E23: ='B-Canada'!F63 -> 0.38870706 | F23: ='B-Canada'!G63 -> 0.69511862
A24: B-US | B24: ='B-US'!C63 -> 0.55514992 | C24: ='B-US'!D63 -> 0.56756614 | D24: ='B-US'!E63 -> 0.52760253 | E24: ='B-US'!F63 -> 0.48982183 | F24: ='B-US'!G63 -> 0.67246788
A25: C-Canada | B25: ='C-Canada'!C63 -> 0.55097652 | C25: ='C-Canada'!D63 -> 0.44703264 | D25: ='C-Canada'!E63 -> 0.40706903 | E25: ='C-Canada'!F63 -> 0.36928834 | F25: ='C-Canada'!G63 -> 0.66829448
A26: C-US | B26: ='C-US'!C63 -> 0.52832579 | C26: ='C-US'!D63 -> 0.43603905 | D26: ='C-US'!E63 -> 0.39607544 | E26: ='C-US'!F63 -> 0.35829474 | F26: ='C-US'!G63 -> 0.64564374
A28: Voice share
A29: A-Canada | B29: ='A-Canada'!C64 -> 0.39300597 | C29: ='A-Canada'!D64 -> 0.48203271 | D29: ='A-Canada'!E64 -> 0.52470376 | E29: ='A-Canada'!F64 -> 0.57264812 | F29: ='A-Canada'!G64 -> 0.35394285
A30: A-US | B30: ='A-US'!C64 -> 0.39495786 | C30: ='A-US'!D64 -> 0.58349421 | D30: ='A-US'!E64 -> 0.64720631 | E30: ='A-US'!F64 -> 0.72174123 | F30: ='A-US'!G64 -> 0.35552522
A31: B-Canada | B31: ='B-Canada'!C64 -> 0.45999978 | C31: ='B-Canada'!D64 -> 0.53454641 | D31: ='B-Canada'!E64 -> 0.58463555 | E31: ='B-Canada'!F64 -> 0.64145967 | F31: ='B-Canada'!G64 -> 0.38236377
A32: B-US | B32: ='B-US'!C64 -> 0.47876829 | C32: ='B-US'!D64 -> 0.43931426 | D32: ='B-US'!E64 -> 0.47259042 | E32: ='B-US'!F64 -> 0.50904203 | F32: ='B-US'!G64 -> 0.39524293
A33: C-Canada | B33: ='C-Canada'!C64 -> 0.48239474 | C33: ='C-Canada'!D64 -> 0.55776665 | D33: ='C-Canada'!E64 -> 0.61252486 | E33: ='C-Canada'!F64 -> 0.6751903 | F33: ='C-Canada'!G64 -> 0.39771117
A34: C-US | B34: ='C-US'!C64 -> 0.50307629 | C34: ='C-US'!D64 -> 0.57182929 | D34: ='C-US'!E64 -> 0.62952629 | E34: ='C-US'!F64 -> 0.69590723 | F34: ='C-US'!G64 -> 0.41166383
A36: AI text share
